2019-11-11T12:43:15|CRITICAL|root|Unhandled exception:Traceback (most recent call last):
  File "C:\ProgramData\Anaconda3\lib\site-packages\ScopeFoundry\hardware.py", line 208, in enable_connection
    raise err
  File "C:\ProgramData\Anaconda3\lib\site-packages\ScopeFoundry\hardware.py", line 204, in enable_connection
    self.connect()
  File "C:\Users\Admin\Desktop\MFCS_python_old\PumpHardware.py", line 46, in connect
    self.read_from_hardware() #read from hardware at connection
  File "C:\ProgramData\Anaconda3\lib\site-packages\ScopeFoundry\hardware.py", line 181, in read_from_hardware
    lq.read_from_hardware()
  File "C:\ProgramData\Anaconda3\lib\site-packages\ScopeFoundry\logged_quantity.py", line 162, in read_from_hardware
    self.update_value(new_val=val, update_hardware=False, send_signal=send_signal)
  File "C:\ProgramData\Anaconda3\lib\site-packages\ScopeFoundry\logged_quantity.py", line 223, in update_value
    new_val = self.coerce_to_type(new_val)
  File "C:\ProgramData\Anaconda3\lib\site-packages\ScopeFoundry\logged_quantity.py", line 135, in coerce_to_type
    return self.dtype(x)
ValueError: invalid literal for int() with base 10: b'\x00\x00'

2019-11-11T12:43:16|CRITICAL|root|Unhandled exception:Traceback (most recent call last):
  File "C:\ProgramData\Anaconda3\lib\site-packages\ScopeFoundry\hardware.py", line 208, in enable_connection
    raise err
  File "C:\ProgramData\Anaconda3\lib\site-packages\ScopeFoundry\hardware.py", line 204, in enable_connection
    self.connect()
  File "C:\Users\Admin\Desktop\MFCS_python_old\PumpHardware.py", line 46, in connect
    self.read_from_hardware() #read from hardware at connection
  File "C:\ProgramData\Anaconda3\lib\site-packages\ScopeFoundry\hardware.py", line 181, in read_from_hardware
    lq.read_from_hardware()
  File "C:\ProgramData\Anaconda3\lib\site-packages\ScopeFoundry\logged_quantity.py", line 162, in read_from_hardware
    self.update_value(new_val=val, update_hardware=False, send_signal=send_signal)
  File "C:\ProgramData\Anaconda3\lib\site-packages\ScopeFoundry\logged_quantity.py", line 223, in update_value
    new_val = self.coerce_to_type(new_val)
  File "C:\ProgramData\Anaconda3\lib\site-packages\ScopeFoundry\logged_quantity.py", line 135, in coerce_to_type
    return self.dtype(x)
ValueError: invalid literal for int() with base 10: b'\x00\x00'

