2019-11-11T12:25:40|CRITICAL|root|Unhandled exception:Traceback (most recent call last):
  File "C:\ProgramData\Anaconda3\lib\site-packages\ScopeFoundry\hardware.py", line 204, in enable_connection
    self.connect()
  File "C:\Users\Admin\Desktop\MFCS_python_old\PumpHardware.py", line 46, in connect
    self.read_from_hardware() #read from hardware at connection
  File "C:\ProgramData\Anaconda3\lib\site-packages\ScopeFoundry\hardware.py", line 181, in read_from_hardware
    lq.read_from_hardware()
  File "C:\ProgramData\Anaconda3\lib\site-packages\ScopeFoundry\logged_quantity.py", line 161, in read_from_hardware
    val = self.hardware_read_func()
  File "C:\Users\Admin\Desktop\MFCS_python_old\PumpDevice.py", line 70, in read_pressure_channel
    C_error = lib_mfcs.mfcs_read_chan(c_ulonglong(mfcsHandle),1,byref(pressure_read), byref(timeStamp))
TypeError: an integer is required (got type c_ulonglong)

During handling of the above exception, another exception occurred:

Traceback (most recent call last):
  File "C:\ProgramData\Anaconda3\lib\site-packages\ScopeFoundry\hardware.py", line 219, in enable_connection
    raise err
  File "C:\ProgramData\Anaconda3\lib\site-packages\ScopeFoundry\hardware.py", line 212, in enable_connection
    self.disconnect()
  File "C:\Users\Admin\Desktop\MFCS_python_old\PumpHardware.py", line 55, in disconnect
    self.MFCS.close()
  File "C:\Users\Admin\Desktop\MFCS_python_old\PumpDevice.py", line 79, in close
    B_OK = lib_mfcs.mfcs_close(c_ulonglong(mfcsHandle))
TypeError: an integer is required (got type c_ulonglong)

2019-11-11T12:25:40|CRITICAL|root|Unhandled exception:Traceback (most recent call last):
  File "C:\ProgramData\Anaconda3\lib\site-packages\ScopeFoundry\hardware.py", line 208, in enable_connection
    raise err
  File "C:\ProgramData\Anaconda3\lib\site-packages\ScopeFoundry\hardware.py", line 204, in enable_connection
    self.connect()
  File "C:\Users\Admin\Desktop\MFCS_python_old\PumpHardware.py", line 46, in connect
    self.read_from_hardware() #read from hardware at connection
  File "C:\ProgramData\Anaconda3\lib\site-packages\ScopeFoundry\hardware.py", line 181, in read_from_hardware
    lq.read_from_hardware()
  File "C:\ProgramData\Anaconda3\lib\site-packages\ScopeFoundry\logged_quantity.py", line 161, in read_from_hardware
    val = self.hardware_read_func()
  File "C:\Users\Admin\Desktop\MFCS_python_old\PumpDevice.py", line 70, in read_pressure_channel
    C_error = lib_mfcs.mfcs_read_chan(c_ulonglong(mfcsHandle),1,byref(pressure_read), byref(timeStamp))
TypeError: an integer is required (got type c_ulonglong)

