2019-11-20T11:43:57|WARNING|LoggedQuantity|set_pressure_1 read_from_hardware called when not connected to hardware
2019-11-20T11:44:03|CRITICAL|root|Unhandled exception:Traceback (most recent call last):
  File "C:\ProgramData\Anaconda3\lib\site-packages\ScopeFoundry\logged_quantity.py", line 241, in update_value
    self.hardware_set_func(self.val)
TypeError: setall_zeropressure() takes 1 positional argument but 2 were given

2019-11-20T11:44:07|CRITICAL|root|Unhandled exception:Traceback (most recent call last):
  File "C:\ProgramData\Anaconda3\lib\site-packages\ScopeFoundry\hardware.py", line 160, in <lambda>
    op_button.clicked.connect(lambda checked, f=op_func: f())
TypeError: setall_zeropressure() missing 1 required positional argument: 'self'

2019-11-20T11:44:08|CRITICAL|root|Unhandled exception:Traceback (most recent call last):
  File "C:\ProgramData\Anaconda3\lib\site-packages\ScopeFoundry\logged_quantity.py", line 241, in update_value
    self.hardware_set_func(self.val)
TypeError: setall_zeropressure() takes 1 positional argument but 2 were given

2019-11-20T11:44:09|CRITICAL|root|Unhandled exception:Traceback (most recent call last):
  File "C:\ProgramData\Anaconda3\lib\site-packages\ScopeFoundry\logged_quantity.py", line 241, in update_value
    self.hardware_set_func(self.val)
TypeError: setall_zeropressure() takes 1 positional argument but 2 were given

