2019-03-11T13:30:35|CRITICAL|root|Unhandled exception:Traceback (most recent call last):
  File "C:\ProgramData\Anaconda3\lib\site-packages\ScopeFoundry\measurement.py", line 25, in run
    self.measurement._thread_run()
  File "C:\ProgramData\Anaconda3\lib\site-packages\ScopeFoundry\measurement.py", line 179, in _thread_run
    self.run()
  File "C:\LabPrograms\Python\Hamamatsu_ScopeFoundry\CameraMeasurement.py", line 160, in run
    if self.debug:
AttributeError: 'HamamatsuMeasurement' object has no attribute 'debug'

2019-03-11T13:30:45|CRITICAL|root|Unhandled exception:Traceback (most recent call last):
  File "C:\ProgramData\Anaconda3\lib\site-packages\ScopeFoundry\measurement.py", line 25, in run
    self.measurement._thread_run()
  File "C:\ProgramData\Anaconda3\lib\site-packages\ScopeFoundry\measurement.py", line 179, in _thread_run
    self.run()
  File "C:\LabPrograms\Python\Hamamatsu_ScopeFoundry\CameraMeasurement.py", line 160, in run
    if self.debug:
AttributeError: 'HamamatsuMeasurement' object has no attribute 'debug'

